{
 "cells": [
  {
   "cell_type": "code",
   "execution_count": 2,
   "metadata": {},
   "outputs": [],
   "source": [
    "import pandas as pd\n",
    "from transformers import AutoTokenizer, AutoConfig, TFAutoModelForSequenceClassification\n",
    "\n",
    "tokenizer = AutoTokenizer.from_pretrained('distilbert-base-uncased', use_fast=True)\n",
    "model = TFAutoModelForSequenceClassification.from_pretrained(\"model\")"
   ]
  },
  {
   "cell_type": "code",
   "execution_count": 3,
   "metadata": {},
   "outputs": [],
   "source": [
    "def predict(text):\n",
    "    return model(tokenizer.encode(text, return_tensors='tf', max_length=512))[0].numpy()[0][0]"
   ]
  },
  {
   "cell_type": "code",
   "execution_count": 4,
   "metadata": {},
   "outputs": [
    {
     "name": "stderr",
     "output_type": "stream",
     "text": [
      "ERROR:root:Internal Python error in the inspect module.\n",
      "Below is the traceback from this internal error.\n",
      "\n"
     ]
    },
    {
     "name": "stdout",
     "output_type": "stream",
     "text": [
      "Traceback (most recent call last):\n",
      "  File \"/Users/spenceradams/.local/share/virtualenvs/Yelp-ds-xpajUQwb/lib/python3.7/site-packages/IPython/core/interactiveshell.py\", line 3331, in run_code\n",
      "    exec(code_obj, self.user_global_ns, self.user_ns)\n",
      "  File \"<ipython-input-4-262648aa38b6>\", line 1, in <module>\n",
      "    reviews = pd.read_csv(\"s3://yelp-dataset-pt-9/data/csv/reviews.csv\")\n",
      "  File \"/Users/spenceradams/.local/share/virtualenvs/Yelp-ds-xpajUQwb/lib/python3.7/site-packages/pandas/io/parsers.py\", line 676, in parser_f\n",
      "    return _read(filepath_or_buffer, kwds)\n",
      "  File \"/Users/spenceradams/.local/share/virtualenvs/Yelp-ds-xpajUQwb/lib/python3.7/site-packages/pandas/io/parsers.py\", line 454, in _read\n",
      "    data = parser.read(nrows)\n",
      "  File \"/Users/spenceradams/.local/share/virtualenvs/Yelp-ds-xpajUQwb/lib/python3.7/site-packages/pandas/io/parsers.py\", line 1133, in read\n",
      "    ret = self._engine.read(nrows)\n",
      "  File \"/Users/spenceradams/.local/share/virtualenvs/Yelp-ds-xpajUQwb/lib/python3.7/site-packages/pandas/io/parsers.py\", line 2037, in read\n",
      "    data = self._reader.read(nrows)\n",
      "  File \"pandas/_libs/parsers.pyx\", line 860, in pandas._libs.parsers.TextReader.read\n",
      "  File \"pandas/_libs/parsers.pyx\", line 875, in pandas._libs.parsers.TextReader._read_low_memory\n",
      "  File \"pandas/_libs/parsers.pyx\", line 929, in pandas._libs.parsers.TextReader._read_rows\n",
      "  File \"pandas/_libs/parsers.pyx\", line 916, in pandas._libs.parsers.TextReader._tokenize_rows\n",
      "  File \"pandas/_libs/parsers.pyx\", line 2071, in pandas._libs.parsers.raise_parser_error\n",
      "pandas.errors.ParserError: Error tokenizing data. C error: Calling read(nbytes) on source failed. Try engine='python'.\n",
      "\n",
      "During handling of the above exception, another exception occurred:\n",
      "\n",
      "Traceback (most recent call last):\n",
      "  File \"/Users/spenceradams/.local/share/virtualenvs/Yelp-ds-xpajUQwb/lib/python3.7/site-packages/IPython/core/interactiveshell.py\", line 2044, in showtraceback\n",
      "    stb = value._render_traceback_()\n",
      "AttributeError: 'ParserError' object has no attribute '_render_traceback_'\n",
      "\n",
      "During handling of the above exception, another exception occurred:\n",
      "\n",
      "Traceback (most recent call last):\n",
      "  File \"/Users/spenceradams/.local/share/virtualenvs/Yelp-ds-xpajUQwb/lib/python3.7/site-packages/IPython/core/ultratb.py\", line 1148, in get_records\n",
      "    return _fixed_getinnerframes(etb, number_of_lines_of_context, tb_offset)\n",
      "  File \"/Users/spenceradams/.local/share/virtualenvs/Yelp-ds-xpajUQwb/lib/python3.7/site-packages/IPython/core/ultratb.py\", line 316, in wrapped\n",
      "    return f(*args, **kwargs)\n",
      "  File \"/Users/spenceradams/.local/share/virtualenvs/Yelp-ds-xpajUQwb/lib/python3.7/site-packages/IPython/core/ultratb.py\", line 350, in _fixed_getinnerframes\n",
      "    records = fix_frame_records_filenames(inspect.getinnerframes(etb, context))\n",
      "  File \"/Users/spenceradams/opt/anaconda3/lib/python3.7/inspect.py\", line 1502, in getinnerframes\n",
      "    frameinfo = (tb.tb_frame,) + getframeinfo(tb, context)\n",
      "  File \"/Users/spenceradams/opt/anaconda3/lib/python3.7/inspect.py\", line 1460, in getframeinfo\n",
      "    filename = getsourcefile(frame) or getfile(frame)\n",
      "  File \"/Users/spenceradams/opt/anaconda3/lib/python3.7/inspect.py\", line 696, in getsourcefile\n",
      "    if getattr(getmodule(object, filename), '__loader__', None) is not None:\n",
      "  File \"/Users/spenceradams/opt/anaconda3/lib/python3.7/inspect.py\", line 739, in getmodule\n",
      "    f = getabsfile(module)\n",
      "  File \"/Users/spenceradams/opt/anaconda3/lib/python3.7/inspect.py\", line 709, in getabsfile\n",
      "    return os.path.normcase(os.path.abspath(_filename))\n",
      "  File \"/Users/spenceradams/opt/anaconda3/lib/python3.7/posixpath.py\", line 55, in normcase\n",
      "    if not isinstance(s, (bytes, str)):\n",
      "KeyboardInterrupt\n"
     ]
    },
    {
     "ename": "ParserError",
     "evalue": "Error tokenizing data. C error: Calling read(nbytes) on source failed. Try engine='python'.",
     "output_type": "error",
     "traceback": [
      "\u001b[0;31m---------------------------------------------------------------------------\u001b[0m"
     ]
    }
   ],
   "source": [
    "reviews = pd.read_csv(\"s3://yelp-dataset-pt-9/data/csv/reviews.csv\")"
   ]
  },
  {
   "cell_type": "code",
   "execution_count": null,
   "metadata": {},
   "outputs": [],
   "source": [
    "reviews.head()"
   ]
  },
  {
   "cell_type": "code",
   "execution_count": null,
   "metadata": {},
   "outputs": [],
   "source": [
    "reviews.shape"
   ]
  },
  {
   "cell_type": "code",
   "execution_count": null,
   "metadata": {},
   "outputs": [],
   "source": [
    "business_counts = reviews.groupby(\"business_id\").count()"
   ]
  },
  {
   "cell_type": "code",
   "execution_count": null,
   "metadata": {},
   "outputs": [],
   "source": []
  }
 ],
 "metadata": {
  "kernelspec": {
   "display_name": "Python 3",
   "language": "python",
   "name": "python3"
  },
  "language_info": {
   "codemirror_mode": {
    "name": "ipython",
    "version": 3
   },
   "file_extension": ".py",
   "mimetype": "text/x-python",
   "name": "python",
   "nbconvert_exporter": "python",
   "pygments_lexer": "ipython3",
   "version": "3.7.6"
  }
 },
 "nbformat": 4,
 "nbformat_minor": 4
}
